Workbook

Sheet Sizing and Cost
A1: Ubuntu Innovations (Pty) Ltd — Backup Sizing, Timing and Cost
A2: Week 3 Task 1 | Blue = editable assumption, green = read from another sheet, black = formula. Replace the assumptions with measured values after the first month (du -sh, backup logs).
A4: A. Assumptions
A5: Input | B5: Value | C5: Unit | D5: Source / note | G5: Standard drive sizes | H5: TB
A6: Internet link speed (symmetric) | B6: 200 | C6: Mbps | D6: Week 1 Business Requirements: about 200 Mbps symmetric fibre | G6: Size 1 | H6: 2
A7: Real-world link efficiency | B7: 0.7 | C7: % | D7: Assumption: protocol overhead and other traffic | G7: Size 2 | H7: 4
A8: Local restore speed (USB drive and NAS) | B8: 100 | C8: MB/s | D8: Assumption for a USB 3 hard drive; measure in the lab | G8: Size 3 | H8: 6
A9: Average daily data change | B9: 0.02 | C9: % | D9: Assumption for office files; measure from backup logs | G9: Size 4 | H9: 8
A10: Annual data growth | B10: 0.3 | C10: % | D10: Assumption for a growing start-up | G10: Size 5 | H10: 12
A11: Cloud retention multiplier | B11: 2 | C11: x | D11: Assumption: versions, weekly, monthly and year-end archives on top of one full copy | G11: Size 6 | H11: 16
A12: Local drive retention multiplier | B12: 1.5 | C12: x | D12: Assumption: shorter retention than the cloud
A13: Microsoft 365 users | B13: 25 | C13: users | D13: Business Requirements: 25 employees
A14: Microsoft 365 data per user | B14: 20 | C14: GB | D14: Assumption: mailbox + OneDrive + SharePoint share; measure in the admin centre
A15: NAS usable capacity | B15: 8000 | C15: GB | D15: Brief: 8TB usable (2 x 8TB in RAID 1)
A16: Safe fill limit | B16: 0.7 | C16: % | D16: Shared Folder Structure: add drives before storage passes 70%
A17: Backup scan and verify overhead per job | B17: 0.5 | C17: hours | D17: Assumption
A18: Cloud storage price | B18: 6.95 | C18: USD/TB/month | D18: Third-party listings show USD 6 to 6.95: confirm on the provider's pricing page
A19: Exchange rate | B19: 18 | C19: ZAR per USD | D19: Planning placeholder only: replace with the current rate
A20: Priority data share | B20: 0.3 | C20: % of data | D20: Assumption: Finance, HR, Management and active Sales/Development projects
A21: Replacement NAS set-up time | B21: 4 | C21: hours | D21: Assumption: install DSM, create volume, restore groups and permissions (excludes delivery)
A22: Interim access set-up time | B22: 1 | C22: hours | D22: Assumption: prepare a temporary IT workstation share
A23: Local backup window (20:00 to 23:00) | B23: 3 | C23: hours | D23: Backup Schedule
A24: Cloud backup window (23:00 to 06:00) | B24: 7 | C24: hours | D24: Backup Schedule
A26: B. Data by shared folder (from the Shared Folder Structure quotas)
A27: Folder | B27: Quota (GB) | C27: Estimated data now (GB) | D27: % of quota used | E27: In 12 months (GB) | F27: In 36 months (GB) | G27: 12-month check
A28: Public | B28: 100 | C28: 20 | D28: =C28/B28 -> 0.2 | E28: =C28*(1+$B$10) -> 26 | F28: =C28*(1+$B$10)^3 -> 43.94 | G28: =IF(E28<=B28,"OK","OVER QUOTA") -> OK
A29: Finance | B29: 500 | C29: 150 | D29: =C29/B29 -> 0.3 | E29: =C29*(1+$B$10) -> 195 | F29: =C29*(1+$B$10)^3 -> 329.55 | G29: =IF(E29<=B29,"OK","OVER QUOTA") -> OK
A30: HR | B30: 300 | C30: 80 | D30: =C30/B30 -> 0.26666667 | E30: =C30*(1+$B$10) -> 104 | F30: =C30*(1+$B$10)^3 -> 175.76 | G30: =IF(E30<=B30,"OK","OVER QUOTA") -> OK
A31: Sales | B31: 1000 | C31: 400 | D31: =C31/B31 -> 0.4 | E31: =C31*(1+$B$10) -> 520 | F31: =C31*(1+$B$10)^3 -> 878.8 | G31: =IF(E31<=B31,"OK","OVER QUOTA") -> OK
A32: Development | B32: 2000 | C32: 600 | D32: =C32/B32 -> 0.3 | E32: =C32*(1+$B$10) -> 780 | F32: =C32*(1+$B$10)^3 -> 1318.2 | G32: =IF(E32<=B32,"OK","OVER QUOTA") -> OK
A33: Management | B33: 200 | C33: 50 | D33: =C33/B33 -> 0.25 | E33: =C33*(1+$B$10) -> 65 | F33: =C33*(1+$B$10)^3 -> 109.85 | G33: =IF(E33<=B33,"OK","OVER QUOTA") -> OK
A34: Total | B34: =SUM(B28:B33) -> 4100 | C34: =SUM(C28:C33) -> 1300 | D34: =C34/B34 -> 0.31707317 | E34: =SUM(E28:E33) -> 1690 | F34: =SUM(F28:F33) -> 2856.1 | G34: =IF(COUNTIF(G28:G33,"OVER QUOTA")=0,"OK","CHECK") -> OK
A36: C. Capacity, backup targets and cloud cost
A37: Measure | B37: Now | C37: In 12 months | D37: In 36 months | E37: Note
A38: File data on the NAS (GB) | B38: =C34 -> 1300 | C38: =E34 -> 1690 | D38: =F34 -> 2856.1 | E38: From table B
A39: Microsoft 365 backup held on the NAS (GB) | B39: =$B$13*$B$14*(1+$B$10)^0 -> 500 | C39: =$B$13*$B$14*(1+$B$10)^1 -> 650 | D39: =$B$13*$B$14*(1+$B$10)^3 -> 1098.5 | E39: Active Backup for Microsoft 365 stores its copy on the NAS
A40: Total data to protect (GB) | B40: =B38+B39 -> 1800 | C40: =C38+C39 -> 2340 | D40: =D38+D39 -> 3954.6 | E40: Files + Microsoft 365 backup
A41: NAS safe limit (GB) | B41: =$B$15*$B$16 -> 5600 | C41: =$B$15*$B$16 -> 5600 | D41: =$B$15*$B$16 -> 5600 | E41: Capacity x safe fill limit
A42: NAS headroom (GB) | B42: =B41-B40 -> 3800 | C42: =C41-C40 -> 3260 | D42: =D41-D40 -> 1645.4 | E42: Safe limit minus data
A43: NAS capacity check | B43: =IF(B42>=0,"OK","EXPAND") -> OK | C43: =IF(C42>=0,"OK","EXPAND") -> OK | D43: =IF(D42>=0,"OK","EXPAND") -> OK | E43: EXPAND means add drives (two bays are free)
...

Sheet Backup Schedule
A1: Backup Schedule and Retention
A2: Daily incremental, weekly full, monthly archive and offsite cloud storage, as required by the brief. Durations for J03 and J04 are formulas from the Sizing and Cost sheet.
A4: ID | B4: Job | C4: What is protected | D4: Type | E4: When | F4: Destination | G4: Tool | H4: Retention | I4: Est. duration (h) | J4: Fits window? | K4: Owner
A5: J01 | B5: Recycle bin | C5: All shared folders | D5: Safety net | E5: Always on | F5: NAS (each shared folder) | G5: DSM | H5: Emptied after 30 days | K5: IT support
A6: J02 | B6: Hourly snapshots | C6: All shared folders | D6: Point-in-time copy | E6: Hourly 08:00 to 18:00 Mon to Fri, plus 20:00 daily | F6: NAS (same volume) | G6: Snapshot Replication (Btrfs) | H6: Hourly: 5 working days; daily: 30 days | K6: IT support
A7: J03 | B7: Daily incremental: local | C7: All folders, Microsoft 365 backup, GitHub mirror and NAS configuration | D7: Incremental | E7: Daily 20:00 | F7: External USB drive on the NAS | G7: Hyper Backup | H7: Daily: 30 days; weekly: 12 weeks; monthly: 12 months | I7: ='Sizing and Cost'!B57 -> 0.6 | J7: ='Sizing and Cost'!D57 -> Fits window | K7: IT support
A8: J04 | B8: Daily incremental: offsite | C8: Same as J03 | D8: Incremental | E8: Daily 23:00 | F8: Cloud storage bucket (encrypted) | G8: Hyper Backup (client-side AES-256) | H8: Daily: 30 days; weekly: 12 weeks | I8: ='Sizing and Cost'!B58 -> 1.0714286 | J8: ='Sizing and Cost'!D58 -> Fits window | K8: IT support
A9: J05 | B9: Weekly full restore point and integrity check | C9: Same as J03 | D9: Full (verified) | E9: Sunday 01:00 | F9: Local drive and cloud (same tasks) | G9: Hyper Backup version and integrity check | H9: Weekly points: 12 weeks | K9: IT support
A10: J06 | B10: Monthly archive | C10: All folders | D10: Archive | E10: 1st of the month 02:00 | F10: Cloud archive bucket | G10: Hyper Backup (separate task) | H10: 12 months | K10: IT support
A11: J07 | B11: Year-end archive | C11: Finance, HR and Management only | D11: Archive | E11: First run of January | F11: Cloud archive bucket | G11: Hyper Backup (separate task) | H11: 7 years | K11: IT support and data owners
A12: J08 | B12: Microsoft 365 backup | C12: Exchange, OneDrive, SharePoint, Teams | D12: Incremental | E12: Daily 19:00 | F12: NAS | G12: Active Backup for Microsoft 365 (free) | H12: 12 months | K12: IT support
A13: J09 | B13: GitHub repository mirror | C13: All company repositories | D13: Mirror | E13: Daily 19:30 | F13: NAS: Development/Projects/GitHub-Mirror | G13: Scheduled git mirror script | H13: Latest mirror (history is in the repositories) | K13: Development lead
A14: J10 | B14: Network configuration export | C14: Firewall, switch and access points | D14: Configuration | E14: Monthly and after every change | F14: NAS: Management/IT-and-Licences | G14: Manual export from each device | H14: Last 12 exports | K14: IT support
A15: J11 | B15: SaaS data export | C15: Accounting, payroll, HR system, CRM | D15: Export | E15: Monthly (payroll: after each run) | F15: NAS: owner's folder (Finance, HR, Sales) | G15: Manual export by the data owner | H15: Last 12 exports | K15: Data owners
A16: J12 | B16: Device rebuild kit | C16: Standard build settings, Intune profiles, Ubuntu build script | D16: Documentation | E16: After every change; reviewed quarterly | F16: NAS: Management/IT-and-Licences | G16: Manual | H16: Current and previous versions | K16: IT support
A17: J13 | B17: Backup health check | C17: All backup jobs | D17: Monitoring | E17: Daily 08:30 (5 minutes); weekly report on Monday | F17: - | G17: Hyper Backup notifications and logs | H17: - | K17: IT support
A18: J14 | B18: Restore test | C18: A sample from every folder and Microsoft 365 | D18: Verification | E18: Quarterly | F18: - | G18: IT support with the data owner | H18: Results kept 3 years | K18: IT support
A19: J15 | B19: Disaster recovery exercise | C19: NAS restore to a test target and a scenario walk-through | D19: Verification | E19: Once a year | F19: - | G19: IT support and Executive sponsor | H19: Report kept 3 years | K19: IT support
A21: Typical day: hourly snapshots 08:00 to 18:00 | 19:00 Microsoft 365 | 19:30 GitHub mirror | 20:00 local backup (includes the two before it) | 23:00 offsite backup. Sunday 01:00 weekly verified restore point and integrity check. 1st of the month 02:00 archive.
A22: Weekly full: Hyper Backup keeps each version as a complete restore point while storing only changed data. The Sunday version is the weekly full restore point and is integrity-checked. A literal full copy each week would waste bandwidth: see the Plan, section 4.2.

Sheet RTO and RPO
A1: Recovery Objectives (RTO and RPO)
A2: RTO = how long the business can be without it. RPO = how much recent data it can afford to lose. Targets need Executive Management approval.
A4: 1. Priority tiers
A5: Tier | B5: Meaning | C5: Target RTO | D5: Examples
A6: Tier 1: Critical | B6: Work stops without it | C6: 4 hours | D6: Internet and network core; Microsoft 365 email and sign-in; critical NAS folders (Finance, HR, Management and active Sales and Development projects)
A7: Tier 2: Important | B7: Work continues slowly, or a deadline is at risk | C7: 2 business days | D7: All other NAS data; accounting, payroll, HR and CRM systems; GitHub; NAS and network configuration
A8: Tier 3: Normal | B8: Inconvenient, but the business carries on | C8: 5 business days | D8: Individual PCs and laptops (rebuilt from the standard build), printers, archives and test data
A10: 2. Objectives by system
A11: System | B11: Tier | C11: RPO | D11: RTO | E11: Protected by
A12: Internet, firewall, switch and access points | B12: Tier 1 | C12: Last configuration export (monthly and after every change) | D12: 4 hours for an ISP fault (LTE/5G failover); 1 business day if hardware must be replaced | E12: LTE/5G failover, configuration exports (J10), supplier replacement, UPS
A13: Microsoft 365: email, calendar, Teams, OneDrive, SharePoint | B13: Tier 1 | C13: 24 hours (nightly backup) | D13: 4 hours to restore deleted items; service outages follow Microsoft's own recovery | E13: Microsoft's own retention plus Active Backup for Microsoft 365 on the NAS (J08)
A14: NAS shares: critical folders | B14: Tier 1 | C14: 1 hour for deleted or changed files (hourly snapshots); 24 hours if the NAS is lost | D14: 1 hour for a single file; 4 hours for interim access after a NAS failure | E14: Recycle bin and snapshots (J01, J02), local drive (J03), cloud (J04)
A15: NAS shares: all other data | B15: Tier 2 | C15: 24 hours | D15: 2 business days (replacement NAS delivered the next business day, then restore) | E15: J03 to J07
A16: Accounting, payroll, HR system and CRM (SaaS) | B16: Tier 2 | C16: Vendor holds the live data; our export is up to 1 month old (payroll: after each run) | D16: 1 business day to regain access; longer if an account must be rebuilt from an export | E16: Vendor resilience plus monthly exports (J11)
A17: GitHub source code | B17: Tier 2 | C17: 24 hours (nightly mirror); developers' local copies are often newer | D17: 1 business day | E17: Nightly mirror to the NAS (J09) and local clones
A18: Workstations and laptops | B18: Tier 3 | C18: Not applicable: no unique data is kept on devices | D18: 1 business day per device (spare device, or rebuild in about 2 to 3 hours) | E18: Standard builds, Autopilot and Intune, OneDrive folder redirection on laptops, Ubuntu build script
A19: Printers | B19: Tier 3 | C19: Not applicable | D19: 3 business days | E19: DHCP reservations, documented settings, supplier replacement
A20: Archives and test data | B20: Tier 3 | C20: 1 month | D20: 5 business days | E20: Monthly and year-end archives (J06, J07)
A22: 3. Objectives by disaster scenario
A23: ID | B23: Scenario | C23: RPO | D23: RTO | E23: Recovery method | F23: Runbook
A24: S1 | B24: Accidental deletion or overwrite | C24: 1 hour | D24: 1 hour | E24: Recycle bin, then snapshot, then a backup version | F24: R1
A25: S2 | B25: One NAS disk fails | C25: 0 (no data lost) | D25: 0 (RAID 1 keeps the NAS running) | E25: Replace the disk within 2 business days; run a backup straight away | F25: R2
A26: S3 | B26: NAS unusable (controller, power supply, corrupt volume) | C26: 24 hours | D26: 4 hours for interim access; 2 business days for full service | E26: Restore priority folders from the local drive to a temporary share, then rebuild on a replacement NAS | F26: R3
A27: S4 | B27: Ransomware or malicious deletion | C27: 24 hours | D27: 1 business day for critical folders; 3 business days for everything | E27: Isolate, confirm clean, restore from a version made before the infection (local, else cloud) | F27: R4
A28: S5 | B28: PC or laptop lost, stolen or failed | C28: 0 for company data (none held locally) | D28: 1 business day | E28: Spare or rebuild; remote wipe; revoke sessions and reset passwords | F28: R5
A29: S6 | B29: Internet outage | C29: Not applicable | D29: 15 minutes with LTE/5G failover; otherwise the ISP's repair time | E29: Automatic failover; log the ISP fault | F29: R6
A30: S7 | B30: Firewall, switch or access point fails | C30: Last configuration export | D30: 1 business day | E30: Replacement unit; restore configuration; verify VLANs | F30: R7
A31: S8 | B31: Site disaster (fire, flood, theft, building closed) | C31: 24 hours | D31: 1 business day to work from anywhere on cloud services; 5 business days for file shares; 10 business days for the full office | E31: Cloud copy, replacement NAS, temporary premises | F31: R8
A32: S9 | B32: Cloud or SaaS outage, or account compromise | C32: Vendor-dependent; last export | D32: Vendor-dependent; 1 business day to restore access | E32: Vendor status page, MFA reset, restore from export, follow the Incident Response Plan | F32: R9
A33: S10 | B33: Power outage | C33: 0 | D33: Power return plus 15 minutes | E33: UPS carries the network and NAS briefly, then a safe shutdown | F33: R6
A35: 4. Can we meet the targets? Restore-time estimator (all values are formulas)
A36: Restore case | B36: Data to restore (GB) | C36: Source | D36: Speed (MB/s) | E36: Extra time (h) | F36: Estimated time (h) | G36: Target (h) | H36: Result
A37: Interim access to priority data from the local drive (now) | B37: ='Sizing and Cost'!B40*'Sizing and Cost'!$B$20 -> 540 | C37: Local drive | D37: ='Sizing and Cost'!$B$8 -> 100 | E37: ='Sizing and Cost'!$B$22 -> 1 | F37: =B37*1000/D37/3600+E37 -> 2.5 | G37: 4 | H37: =IF(F37<=G37,"OK","EXCEEDS") -> OK
A38: Interim access to priority data from the local drive (12m) | B38: ='Sizing and Cost'!C40*'Sizing and Cost'!$B$20 -> 702 | C38: Local drive | D38: ='Sizing and Cost'!$B$8 -> 100 | E38: ='Sizing and Cost'!$B$22 -> 1 | F38: =B38*1000/D38/3600+E38 -> 2.95 | G38: 4 | H38: =IF(F38<=G38,"OK","EXCEEDS") -> OK
A39: Full restore onto a replacement NAS from the local drive (now) | B39: ='Sizing and Cost'!B40 -> 1800 | C39: Local drive | D39: ='Sizing and Cost'!$B$8 -> 100 | E39: ='Sizing and Cost'!$B$21 -> 4 | F39: =B39*1000/D39/3600+E39 -> 9 | G39: 48 | H39: =IF(F39<=G39,"OK","EXCEEDS") -> OK
A40: Full restore onto a replacement NAS from the local drive (12m) | B40: ='Sizing and Cost'!C40 -> 2340 | C40: Local drive | D40: ='Sizing and Cost'!$B$8 -> 100 | E40: ='Sizing and Cost'!$B$21 -> 4 | F40: =B40*1000/D40/3600+E40 -> 10.5 | G40: 48 | H40: =IF(F40<=G40,"OK","EXCEEDS") -> OK
A41: Priority data onto a replacement NAS from the cloud (now) | B41: ='Sizing and Cost'!B40*'Sizing and Cost'!$B$20 -> 540 | C41: Cloud | D41: ='Sizing and Cost'!$B$55 -> 17.5 | E41: ='Sizing and Cost'!$B$21 -> 4 | F41: =B41*1000/D41/3600+E41 -> 12.571429 | G41: 24 | H41: =IF(F41<=G41,"OK","EXCEEDS") -> OK
A42: Priority data onto a replacement NAS from the cloud (12m) | B42: ='Sizing and Cost'!C40*'Sizing and Cost'!$B$20 -> 702 | C42: Cloud | D42: ='Sizing and Cost'!$B$55 -> 17.5 | E42: ='Sizing and Cost'!$B$21 -> 4 | F42: =B42*1000/D42/3600+E42 -> 15.142857 | G42: 24 | H42: =IF(F42<=G42,"OK","EXCEEDS") -> OK
A43: Full restore onto a replacement NAS from the cloud (now) | B43: ='Sizing and Cost'!B40 -> 1800 | C43: Cloud | D43: ='Sizing and Cost'!$B$55 -> 17.5 | E43: ='Sizing and Cost'!$B$21 -> 4 | F43: =B43*1000/D43/3600+E43 -> 32.571429 | G43: 120 | H43: =IF(F43<=G43,"OK","EXCEEDS") -> OK
A44: Full restore onto a replacement NAS from the cloud (12m) | B44: ='Sizing and Cost'!C40 -> 2340 | C44: Cloud | D44: ='Sizing and Cost'!$B$55 -> 17.5 | E44: ='Sizing and Cost'!$B$21 -> 4 | F44: =B44*1000/D44/3600+E44 -> 41.142857 | G44: 120 | H44: =IF(F44<=G44,"OK","EXCEEDS") -> OK
...

Sheet Restore Test Log
A1: Restore Test Log
A2: Fill in during each quarterly test. Sources rotate so the cloud copy is proven at least twice a year. Result has a Pass/Fail drop-down.
A4: Test ID | B4: Quarter | C4: Test type | D4: Folder or system | E4: Restore from | F4: Item restored | G4: Date | H4: Time taken (min) | I4: Result | J4: Issues and follow-up | K4: Tester | L4: Data owner sign-off
A5: RT-01 | B5: Q1 | C5: Folder restore | D5: /Company/Public | E5: Local drive
A6: RT-02 | B6: Q1 | C6: Folder restore | D6: /Company/Finance | E6: Local drive
A7: RT-03 | B7: Q1 | C7: Folder restore | D7: /Company/HR | E7: Local drive
A8: RT-04 | B8: Q1 | C8: Folder restore | D8: /Company/Sales | E8: Local drive
A9: RT-05 | B9: Q1 | C9: Folder restore | D9: /Company/Development | E9: Local drive
A10: RT-06 | B10: Q1 | C10: Folder restore | D10: /Company/Management | E10: Local drive
A11: RT-07 | B11: Q1 | C11: Microsoft 365 restore | D11: One mailbox item and one OneDrive file | E11: NAS (Active Backup for Microsoft 365)
A12: RT-08 | B12: Q2 | C12: Folder restore | D12: /Company/Public | E12: Cloud
A13: RT-09 | B13: Q2 | C13: Folder restore | D13: /Company/Finance | E13: Cloud
A14: RT-10 | B14: Q2 | C14: Folder restore | D14: /Company/HR | E14: Cloud
A15: RT-11 | B15: Q2 | C15: Folder restore | D15: /Company/Sales | E15: Cloud
A16: RT-12 | B16: Q2 | C16: Folder restore | D16: /Company/Development | E16: Cloud
... A35: RT-31 | B35: Q4 | C35: DR exercise | D35: NAS restore to a test target and scenario walk-through | E35: Local drive and cloud
C37: Tests planned | D37: =COUNTA(A5:A35) -> 31
C38: Tests passed | D38: =COUNTIF(I5:I35,"Pass") -> 0
C39: Tests failed | D39: =COUNTIF(I5:I35,"Fail") -> 0
C40: Pass rate of completed tests | D40: =IF(D38+D39=0,"No tests yet",D38/(D38+D39)) -> No tests yet

Sheet Notes
A1: Notes, Assumptions and Follow-ups
A2: Items to confirm, and the other documents that must match this plan.
A4: # | B4: Type | C4: Detail
A5: 1 | B5: Assumption | C5: Every size, speed, change rate and price on the Sizing and Cost sheet is a planning estimate. Replace them with measured values after the first month.
A6: 2 | B6: New hardware | C6: One external USB drive (size from the Sizing sheet) is added as the second backup copy. A second drive that is rotated weekly and kept off-site is an optional extra. Update the Hardware Inventory.
A7: 3 | B7: Software | C7: Synology Active Backup for Microsoft 365 (a free add-on for the NAS) and Snapshot Replication are added to the NAS software line (SW-24) in the Software Inventory.
A8: 4 | B8: Confirm in DSM | C8: Whether the Microsoft 365 backup folder can be included in the offsite Hyper Backup task. If not, the Microsoft 365 backup has no offsite copy and the plan must say so.
A9: 5 | B9: Confirm in DSM | C9: That the volume is created as Btrfs (needed for snapshots), and the exact retention-rule options for Hyper Backup.
A10: 6 | B10: Decision | C10: Cloud provider and region: Backblaze B2 is in the Software Inventory; a South African region (for example an Azure region) may suit POPIA cross-border rules better. Decide and record.
A11: 7 | B11: Decision | C11: Executive Management must approve the RTO and RPO targets, and decide whether a spare NAS or a rotated second drive is worth the cost.
A12: 8 | B12: Match: Shared Folder Structure | C12: Recycle bin, snapshots, quarterly restore tests and the 70% capacity rule are used here. Add a GitHub-Mirror subfolder under Development/Projects.
A13: 9 | B13: Match: Software Deployment Plan | C13: Add OneDrive folder redirection for laptops. The rule 'take a snapshot before updating the NAS' is already there.
A14: 10 | B14: Match: IP Addressing Plan | C14: Firewall rule 5 already lets nas01 reach the internet on HTTPS, DNS and NTP for cloud backup.
A15: 11 | B15: Match: Troubleshooting Log | C15: Tier 1 RTO of 4 hours matches the P1 resolution target.
A16: 12 | B16: Next documents | C16: Cybersecurity Policy, Risk Assessment and Incident Response Plan should refer to this plan (ransomware and data-loss rows, restore steps, key custody).
